<?xml version="1.0" ?>
<!-- =================================================================================== -->
<!-- |    This document was autogenerated by xacro from car.xacro                      | -->
<!-- |    EDITING THIS FILE BY HAND IS NOT RECOMMENDED                                 | -->
<!-- =================================================================================== -->
<robot name="car_xacro">
  <link name="camera">
    <visual>
      <geometry>
        <box size="0.02 0.05 0.05"/>
      </geometry>
      <origin rpy="0 0 0" xyz="0 0 0"/>
      <material name="camerColor">
        <color rgba="0 0 0 0.5"/>
      </material>
    </visual>
  </link>
  <joint name="camera2base" type="fixed">
    <parent link="base"/>
    <child link="camera"/>
    <origin rpy="0 0 0" xyz="0.08 0 0.052500000000000005"/>
  </joint>
  <!--支架的设计-->
  <link name="support">
    <visual>
      <geometry>
        <cylinder length="0.15" radius="0.01"/>
      </geometry>
      <origin rpy="0 0 0" xyz="0 0 0"/>
      <material name="laserColor">
        <color rgba="0.5 0.5 0.5 0.8"/>
      </material>
    </visual>
  </link>
  <joint name="support" type="fixed">
    <parent link="base"/>
    <child link="support"/>
    <origin rpy="0 0 0" xyz="0 0 0.1025"/>
  </joint>
  <!--雷达的设计-->
  <link name="laser">
    <visual>
      <geometry>
        <cylinder length="0.05" radius="0.03"/>
      </geometry>
      <origin rpy="0 0 0" xyz="0 0 0"/>
      <material name="laserColor">
        <color rgba="0 1 0 0.8"/>
      </material>
    </visual>
  </link>
  <joint name="laser" type="fixed">
    <parent link="base"/>
    <child link="laser"/>
    <origin rpy="0 0 0" xyz="0 0 0.20249999999999999"/>
  </joint>
  <link name="base_footprint">
    <visual>
      <geometry>
        <sphere radius="0.001"/>
        <origin rpy="0 0 0" xyz="0 0 0"/>
      </geometry>
    </visual>
  </link>
  <link name="base">
    <visual>
      <geometry>
        <cylinder length="0.08" radius="0.1"/>
        <origin rpy="0 0 0" xyz="0 0 0"/>
      </geometry>
    </visual>
  </link>
  <!-- base collision-->
  <collision>
    <origin rpy="0.0 0.0 0.0" xyz="0.0 0.0 0.0"/>
    <geometry>
      <cylinder length="0.08" radius="0.1"/>
    </geometry>
  </collision>
  <inertial>
    <mass value="2"/>
    <inertia ixx="0.006066666666666668" ixy="0" ixz="0" iyy="0.006066666666666668" iyz="0" izz="0.010000000000000002"/>
  </inertial>
  <!--gazebo color-->
  <joint name="link2footprint" type="fixed">
    <parent link="base_footprint"/>
    <child link="base"/>
    <origin rpy="0 0 0" xyz="0 0 0.055"/>
  </joint>
  <link name="left_wheel">
    <visual>
      <geometry>
        <cylinder length="0.015" radius="0.0325"/>
        <orgin rpy="0 0 0" xyz="0 0 0"/>
      </geometry>
    </visual>
  </link>
  <joint name="left2base" type="continuous">
    <parent link="base"/>
    <child link="left_wheel"/>
    <origin rpy="1.57 0 0" xyz="0 0.1 -0.0225"/>
    <axis xyz="0 0 1"/>
  </joint>
  <link name="right_wheel">
    <visual>
      <geometry>
        <cylinder length="0.015" radius="0.0325"/>
        <orgin rpy="0 0 0" xyz="0 0 0"/>
      </geometry>
    </visual>
  </link>
  <joint name="right2base" type="continuous">
    <parent link="base"/>
    <child link="right_wheel"/>
    <origin rpy="1.57 0 0" xyz="0 -0.1 -0.0225"/>
    <axis xyz="0 0 1"/>
  </joint>
</robot>

