<?xml version="1.0" ?>
<!-- =================================================================================== -->
<!-- |    This document was autogenerated by xacro from car.xacro                      | -->
<!-- |    EDITING THIS FILE BY HAND IS NOT RECOMMENDED                                 | -->
<!-- =================================================================================== -->
<robot name="car_xacro">
  <link name="base_footprint">
    <visual>
      <geometry>
        <sphere radius="0.001"/>
        <origin rpy="0 0 0" xyz="0 0 0"/>
      </geometry>
    </visual>
  </link>
  <link name="base">
    <visual>
      <geometry>
        <cylinder length="0.08" radius="0.1"/>
        <origin rpy="0 0 0" xyz="0 0 0"/>
      </geometry>
    </visual>
  </link>
  <joint name="link2footprint" type="fixed">
    <parent link="base_footprint"/>
    <child link="base"/>
    <origin rpy="0 0 0" xyz="0 0 0.055"/>
  </joint>
  <link name="left_wheel">
    <visual>
      <geometry>
        <cylinder length="0.015" radius="0.0325"/>
        <orgin rpy="0 0 0" xyz="0 0 0"/>
      </geometry>
    </visual>
  </link>
  <joint name="left2base" type="continuous">
    <parent link="base"/>
    <child link="left_wheel"/>
    <origin rpy="1.57 0 0" xyz="0 0.1 -0.0225"/>
    <axis xyz="0 0 1"/>
  </joint>
  <link name="right_wheel">
    <visual>
      <geometry>
        <cylinder length="0.015" radius="0.0325"/>
        <orgin rpy="0 0 0" xyz="0 0 0"/>
      </geometry>
    </visual>
  </link>
  <joint name="right2base" type="continuous">
    <parent link="base"/>
    <child link="right_wheel"/>
    <origin rpy="1.57 0 0" xyz="0 -0.1 -0.0225"/>
    <axis xyz="0 0 1"/>
  </joint>
</robot>

